============================= test session starts ==============================
platform linux -- Python 3.11.1, pytest-8.3.2, pluggy-1.5.0 -- /home/mostyn/northcoders/project/de-rossolimo-project/venv/bin/python
cachedir: .pytest_cache
rootdir: /home/mostyn/northcoders/project/de-rossolimo-project
plugins: testdox-3.1.0, cov-5.0.0
collecting ... collected 2 items

test_warehouse_data/test_m_final_load_dims.py::test_load_dims_loads_location_dim_table PASSED
test_warehouse_data/test_m_final_load_dims.py::test_load_dims_counterparty_erroring FAILED

=================================== FAILURES ===================================
_____________________ test_load_dims_counterparty_erroring _____________________

seeder = None, conn = <pg8000.native.Connection object at 0x7ccd74f02410>

    def test_load_dims_counterparty_erroring(seeder, conn):
>       sales_fact_df = sales_facts(file_dict)

test_warehouse_data/test_m_final_load_dims.py:83: 
_ _ _ _ _ _ _ _ _ _ _ _ _ _ _ _ _ _ _ _ _ _ _ _ _ _ _ _ _ _ _ _ _ _ _ _ _ _ _ _ 
utils/fact_generator.py:18: in sales_facts
    sales_order.reset_index()
venv/lib/python3.11/site-packages/pandas/core/frame.py:6472: in reset_index
    new_obj.insert(
_ _ _ _ _ _ _ _ _ _ _ _ _ _ _ _ _ _ _ _ _ _ _ _ _ _ _ _ _ _ _ _ _ _ _ _ _ _ _ _ 

self =                                 created_at  ... sales_order_id
sales_order_id                              ...        ...:10.314000  ...           9822
9823            2024-08-21 09:56:09.992000  ...           9823

[9819 rows x 12 columns]
loc = 0, column = 'sales_order_id'
value = array([   1,    2,    3, ..., 9820, 9822, 9823])
allow_duplicates = False

    def insert(
        self,
        loc: int,
        column: Hashable,
        value: Scalar | AnyArrayLike,
        allow_duplicates: bool | lib.NoDefault = lib.no_default,
    ) -> None:
        """
        Insert column into DataFrame at specified location.
    
        Raises a ValueError if `column` is already contained in the DataFrame,
        unless `allow_duplicates` is set to True.
    
        Parameters
        ----------
        loc : int
            Insertion index. Must verify 0 <= loc <= len(columns).
        column : str, number, or hashable object
            Label of the inserted column.
        value : Scalar, Series, or array-like
            Content of the inserted column.
        allow_duplicates : bool, optional, default lib.no_default
            Allow duplicate column labels to be created.
    
        See Also
        --------
        Index.insert : Insert new item by index.
    
        Examples
        --------
        >>> df = pd.DataFrame({'col1': [1, 2], 'col2': [3, 4]})
        >>> df
           col1  col2
        0     1     3
        1     2     4
        >>> df.insert(1, "newcol", [99, 99])
        >>> df
           col1  newcol  col2
        0     1      99     3
        1     2      99     4
        >>> df.insert(0, "col1", [100, 100], allow_duplicates=True)
        >>> df
           col1  col1  newcol  col2
        0   100     1      99     3
        1   100     2      99     4
    
        Notice that pandas uses index alignment in case of `value` from type `Series`:
    
        >>> df.insert(0, "col0", pd.Series([5, 6], index=[1, 2]))
        >>> df
           col0  col1  col1  newcol  col2
        0   NaN   100     1      99     3
        1   5.0   100     2      99     4
        """
        if allow_duplicates is lib.no_default:
            allow_duplicates = False
        if allow_duplicates and not self.flags.allows_duplicate_labels:
            raise ValueError(
                "Cannot specify 'allow_duplicates=True' when "
                "'self.flags.allows_duplicate_labels' is False."
            )
        if not allow_duplicates and column in self.columns:
            # Should this be a different kind of error??
>           raise ValueError(f"cannot insert {column}, already exists")
E           ValueError: cannot insert sales_order_id, already exists

venv/lib/python3.11/site-packages/pandas/core/frame.py:5158: ValueError
=========================== short test summary info ============================
FAILED test_warehouse_data/test_m_final_load_dims.py::test_load_dims_counterparty_erroring - ValueError: cannot insert sales_order_id, already exists
========================= 1 failed, 1 passed in 1.84s ==========================
